Workbook

Sheet Annual Dashboard
B2: Annual Totals

Sheet Annual Totals
B2: Annual Totals
B3: SUMMARY | C3: JAN | D3: FEB | E3: MAR | F3: APR | G3: MAY | H3: JUN | I3: JUL | J3: AUG | K3: SEP | L3: OCT | M3: NOV | N3: DEC
B4: Income | C4: =INDIRECT(C$3&"!D18") -> 19000 | D4: =INDIRECT(D$3&"!D18") -> 19000 | E4: =INDIRECT(E$3&"!D18") -> 19000 | F4: =INDIRECT(F$3&"!D18") -> 19000 | G4: =INDIRECT(G$3&"!D18") -> 19000 | H4: =INDIRECT(H$3&"!D18") -> 19000 | I4: =INDIRECT(I$3&"!D18") -> 19000 | J4: =INDIRECT(J$3&"!D18") -> 19000 | ... N4: =INDIRECT(N$3&"!D18") -> 19000
B5: Savings | C5: =INDIRECT(C$3&"!D30") -> 0 | D5: =INDIRECT(D$3&"!D30") -> 0 | E5: =INDIRECT(E$3&"!D30") -> 34900 | F5: =INDIRECT(F$3&"!D30") -> 0 | G5: =INDIRECT(G$3&"!D30") -> 0 | H5: =INDIRECT(H$3&"!D30") -> 0 | I5: =INDIRECT(I$3&"!D30") -> 0 | J5: =INDIRECT(J$3&"!D30") -> 1835 | ... N5: =INDIRECT(N$3&"!D30") -> 0
B6: Bills | C6: =INDIRECT(C$3&"!H30") -> 0 | D6: =INDIRECT(D$3&"!H30") -> 0 | E6: =INDIRECT(E$3&"!H30") -> 0 | F6: =INDIRECT(F$3&"!H30") -> 0 | G6: =INDIRECT(G$3&"!H30") -> 0 | H6: =INDIRECT(H$3&"!H30") -> 0 | I6: =INDIRECT(I$3&"!H30") -> 0 | J6: =INDIRECT(J$3&"!H30") -> 0 | ... N6: =INDIRECT(N$3&"!H30") -> 0
B7: Expenses | C7: =INDIRECT(C$3&"!L30") -> 0 | D7: =INDIRECT(D$3&"!L30") -> 0 | E7: =INDIRECT(E$3&"!L30") -> 0 | F7: =INDIRECT(F$3&"!L30") -> 0 | G7: =INDIRECT(G$3&"!L30") -> 0 | H7: =INDIRECT(H$3&"!L30") -> 0 | I7: =INDIRECT(I$3&"!L30") -> 0 | J7: =INDIRECT(J$3&"!L30") -> 0 | ... N7: =INDIRECT(N$3&"!L30") -> 0
B8: Debts | C8: =INDIRECT(C$3&"!P30") -> 0 | D8: =INDIRECT(D$3&"!P30") -> 0 | E8: =INDIRECT(E$3&"!P30") -> 0 | F8: =INDIRECT(F$3&"!P30") -> 0 | G8: =INDIRECT(G$3&"!P30") -> 0 | H8: =INDIRECT(H$3&"!P30") -> 0 | I8: =INDIRECT(I$3&"!P30") -> 0 | J8: =INDIRECT(J$3&"!P30") -> 1700 | ... N8: =INDIRECT(N$3&"!P30") -> 0
B9: BALANCE | C9: =C4-SUM(C5:C8) -> 19000 | D9: =D4-SUM(D5:D8) -> 19000 | E9: =E4-SUM(E5:E8) -> -15900 | F9: =F4-SUM(F5:F8) -> 19000 | G9: =G4-SUM(G5:G8) -> 19000 | H9: =H4-SUM(H5:H8) -> 19000 | I9: =I4-SUM(I5:I8) -> 19000 | J9: =J4-SUM(J5:J8) -> 15465 | ... N9: =N4-SUM(N5:N8) -> 19000
B11: Income
B12: Name | C12: JAN | D12: FEB | E12: MAR | F12: APR | G12: MAY | H12: JUN | I12: JUL | J12: AUG | K12: SEP | L12: OCT | M12: NOV | N12: DEC
B13: Alex Paycheck #1 | C13: =SUMIF(INDIRECT(C$12&"!B10:B17"),$B13,INDIRECT(C$12&"!D10:D17")) -> 0 | D13: =SUMIF(INDIRECT(D$12&"!B10:B17"),$B13,INDIRECT(D$12&"!D10:D17")) -> 0 | E13: =SUMIF(INDIRECT(E$12&"!B10:B17"),$B13,INDIRECT(E$12&"!D10:D17")) -> 0 | F13: =SUMIF(INDIRECT(F$12&"!B10:B17"),$B13,INDIRECT(F$12&"!D10:D17")) -> 0 | G13: =SUMIF(INDIRECT(G$12&"!B10:B17"),$B13,INDIRECT(G$12&"!D10:D17")) -> 0 | H13: =SUMIF(INDIRECT(H$12&"!B10:B17"),$B13,INDIRECT(H$12&"!D10:D17")) -> 0 | I13: =SUMIF(INDIRECT(I$12&"!B10:B17"),$B13,INDIRECT(I$12&"!D10:D17")) -> 0 | J13: =SUMIF(INDIRECT(J$12&"!B10:B17"),$B13,INDIRECT(J$12&"!D10:D17")) -> 0 | ... N13: =SUMIF(INDIRECT(N$12&"!B10:B17"),$B13,INDIRECT(N$12&"!D10:D17")) -> 0
B14: Harper Paycheck #1 | C14: =SUMIF(INDIRECT(C$12&"!B10:B17"),$B14,INDIRECT(C$12&"!D10:D17")) -> 0 | D14: =SUMIF(INDIRECT(D$12&"!B10:B17"),$B14,INDIRECT(D$12&"!D10:D17")) -> 0 | E14: =SUMIF(INDIRECT(E$12&"!B10:B17"),$B14,INDIRECT(E$12&"!D10:D17")) -> 0 | F14: =SUMIF(INDIRECT(F$12&"!B10:B17"),$B14,INDIRECT(F$12&"!D10:D17")) -> 0 | G14: =SUMIF(INDIRECT(G$12&"!B10:B17"),$B14,INDIRECT(G$12&"!D10:D17")) -> 0 | H14: =SUMIF(INDIRECT(H$12&"!B10:B17"),$B14,INDIRECT(H$12&"!D10:D17")) -> 0 | I14: =SUMIF(INDIRECT(I$12&"!B10:B17"),$B14,INDIRECT(I$12&"!D10:D17")) -> 0 | J14: =SUMIF(INDIRECT(J$12&"!B10:B17"),$B14,INDIRECT(J$12&"!D10:D17")) -> 0 | ... N14: =SUMIF(INDIRECT(N$12&"!B10:B17"),$B14,INDIRECT(N$12&"!D10:D17")) -> 0
B15: Freelance Earnings | C15: =SUMIF(INDIRECT(C$12&"!B10:B17"),$B15,INDIRECT(C$12&"!D10:D17")) -> 0 | D15: =SUMIF(INDIRECT(D$12&"!B10:B17"),$B15,INDIRECT(D$12&"!D10:D17")) -> 0 | E15: =SUMIF(INDIRECT(E$12&"!B10:B17"),$B15,INDIRECT(E$12&"!D10:D17")) -> 0 | F15: =SUMIF(INDIRECT(F$12&"!B10:B17"),$B15,INDIRECT(F$12&"!D10:D17")) -> 0 | G15: =SUMIF(INDIRECT(G$12&"!B10:B17"),$B15,INDIRECT(G$12&"!D10:D17")) -> 0 | H15: =SUMIF(INDIRECT(H$12&"!B10:B17"),$B15,INDIRECT(H$12&"!D10:D17")) -> 0 | I15: =SUMIF(INDIRECT(I$12&"!B10:B17"),$B15,INDIRECT(I$12&"!D10:D17")) -> 0 | J15: =SUMIF(INDIRECT(J$12&"!B10:B17"),$B15,INDIRECT(J$12&"!D10:D17")) -> 0 | ... N15: =SUMIF(INDIRECT(N$12&"!B10:B17"),$B15,INDIRECT(N$12&"!D10:D17")) -> 0
B16: Alex Paycheck #2 | C16: =SUMIF(INDIRECT(C$12&"!B10:B17"),$B16,INDIRECT(C$12&"!D10:D17")) -> 0 | D16: =SUMIF(INDIRECT(D$12&"!B10:B17"),$B16,INDIRECT(D$12&"!D10:D17")) -> 0 | E16: =SUMIF(INDIRECT(E$12&"!B10:B17"),$B16,INDIRECT(E$12&"!D10:D17")) -> 0 | F16: =SUMIF(INDIRECT(F$12&"!B10:B17"),$B16,INDIRECT(F$12&"!D10:D17")) -> 0 | G16: =SUMIF(INDIRECT(G$12&"!B10:B17"),$B16,INDIRECT(G$12&"!D10:D17")) -> 0 | H16: =SUMIF(INDIRECT(H$12&"!B10:B17"),$B16,INDIRECT(H$12&"!D10:D17")) -> 0 | I16: =SUMIF(INDIRECT(I$12&"!B10:B17"),$B16,INDIRECT(I$12&"!D10:D17")) -> 0 | J16: =SUMIF(INDIRECT(J$12&"!B10:B17"),$B16,INDIRECT(J$12&"!D10:D17")) -> 0 | ... N16: =SUMIF(INDIRECT(N$12&"!B10:B17"),$B16,INDIRECT(N$12&"!D10:D17")) -> 0
B17: Harper Paycheck #2 | C17: =SUMIF(INDIRECT(C$12&"!B10:B17"),$B17,INDIRECT(C$12&"!D10:D17")) -> 0 | D17: =SUMIF(INDIRECT(D$12&"!B10:B17"),$B17,INDIRECT(D$12&"!D10:D17")) -> 0 | E17: =SUMIF(INDIRECT(E$12&"!B10:B17"),$B17,INDIRECT(E$12&"!D10:D17")) -> 0 | F17: =SUMIF(INDIRECT(F$12&"!B10:B17"),$B17,INDIRECT(F$12&"!D10:D17")) -> 0 | G17: =SUMIF(INDIRECT(G$12&"!B10:B17"),$B17,INDIRECT(G$12&"!D10:D17")) -> 0 | H17: =SUMIF(INDIRECT(H$12&"!B10:B17"),$B17,INDIRECT(H$12&"!D10:D17")) -> 0 | I17: =SUMIF(INDIRECT(I$12&"!B10:B17"),$B17,INDIRECT(I$12&"!D10:D17")) -> 0 | J17: =SUMIF(INDIRECT(J$12&"!B10:B17"),$B17,INDIRECT(J$12&"!D10:D17")) -> 0 | ... N17: =SUMIF(INDIRECT(N$12&"!B10:B17"),$B17,INDIRECT(N$12&"!D10:D17")) -> 0
B18: Investment Interest | C18: =SUMIF(INDIRECT(C$12&"!B10:B17"),$B18,INDIRECT(C$12&"!D10:D17")) -> 0 | D18: =SUMIF(INDIRECT(D$12&"!B10:B17"),$B18,INDIRECT(D$12&"!D10:D17")) -> 0 | E18: =SUMIF(INDIRECT(E$12&"!B10:B17"),$B18,INDIRECT(E$12&"!D10:D17")) -> 0 | F18: =SUMIF(INDIRECT(F$12&"!B10:B17"),$B18,INDIRECT(F$12&"!D10:D17")) -> 0 | G18: =SUMIF(INDIRECT(G$12&"!B10:B17"),$B18,INDIRECT(G$12&"!D10:D17")) -> 0 | H18: =SUMIF(INDIRECT(H$12&"!B10:B17"),$B18,INDIRECT(H$12&"!D10:D17")) -> 0 | I18: =SUMIF(INDIRECT(I$12&"!B10:B17"),$B18,INDIRECT(I$12&"!D10:D17")) -> 0 | J18: =SUMIF(INDIRECT(J$12&"!B10:B17"),$B18,INDIRECT(J$12&"!D10:D17")) -> 0 | ... N18: =SUMIF(INDIRECT(N$12&"!B10:B17"),$B18,INDIRECT(N$12&"!D10:D17")) -> 0
C19: =SUMIF(INDIRECT(C$12&"!B10:B17"),$B19,INDIRECT(C$12&"!D10:D17")) -> 0 | D19: =SUMIF(INDIRECT(D$12&"!B10:B17"),$B19,INDIRECT(D$12&"!D10:D17")) -> 0 | E19: =SUMIF(INDIRECT(E$12&"!B10:B17"),$B19,INDIRECT(E$12&"!D10:D17")) -> 0 | F19: =SUMIF(INDIRECT(F$12&"!B10:B17"),$B19,INDIRECT(F$12&"!D10:D17")) -> 0 | G19: =SUMIF(INDIRECT(G$12&"!B10:B17"),$B19,INDIRECT(G$12&"!D10:D17")) -> 0 | H19: =SUMIF(INDIRECT(H$12&"!B10:B17"),$B19,INDIRECT(H$12&"!D10:D17")) -> 0 | I19: =SUMIF(INDIRECT(I$12&"!B10:B17"),$B19,INDIRECT(I$12&"!D10:D17")) -> 0 | J19: =SUMIF(INDIRECT(J$12&"!B10:B17"),$B19,INDIRECT(J$12&"!D10:D17")) -> 0 | ... N19: =SUMIF(INDIRECT(N$12&"!B10:B17"),$B19,INDIRECT(N$12&"!D10:D17")) -> 0
C20: =SUMIF(INDIRECT(C$12&"!B10:B17"),$B20,INDIRECT(C$12&"!D10:D17")) -> 0 | D20: =SUMIF(INDIRECT(D$12&"!B10:B17"),$B20,INDIRECT(D$12&"!D10:D17")) -> 0 | E20: =SUMIF(INDIRECT(E$12&"!B10:B17"),$B20,INDIRECT(E$12&"!D10:D17")) -> 0 | F20: =SUMIF(INDIRECT(F$12&"!B10:B17"),$B20,INDIRECT(F$12&"!D10:D17")) -> 0 | G20: =SUMIF(INDIRECT(G$12&"!B10:B17"),$B20,INDIRECT(G$12&"!D10:D17")) -> 0 | H20: =SUMIF(INDIRECT(H$12&"!B10:B17"),$B20,INDIRECT(H$12&"!D10:D17")) -> 0 | I20: =SUMIF(INDIRECT(I$12&"!B10:B17"),$B20,INDIRECT(I$12&"!D10:D17")) -> 0 | J20: =SUMIF(INDIRECT(J$12&"!B10:B17"),$B20,INDIRECT(J$12&"!D10:D17")) -> 0 | ... N20: =SUMIF(INDIRECT(N$12&"!B10:B17"),$B20,INDIRECT(N$12&"!D10:D17")) -> 0
B21: Total Income | C21: =SUM(C13:C20) -> 0 | D21: =SUM(D13:D20) -> 0 | E21: =SUM(E13:E20) -> 0 | F21: =SUM(F13:F20) -> 0 | G21: =SUM(G13:G20) -> 0 | H21: =SUM(H13:H20) -> 0 | I21: =SUM(I13:I20) -> 0 | J21: =SUM(J13:J20) -> 0 | ... N21: =SUM(N13:N20) -> 0
B23: Savings
B24: Name | C24: JAN | D24: FEB | E24: MAR | F24: APR | G24: MAY | H24: JUN | I24: JUL | J24: AUG | K24: SEP | L24: OCT | M24: NOV | N24: DEC
B25: Emergency Fund | C25: =SUMIF(INDIRECT(C$24&"!B22:B29"),$B25,INDIRECT(C$24&"!D22:D29")) -> 0 | D25: =SUMIF(INDIRECT(D$24&"!B22:B29"),$B25,INDIRECT(D$24&"!D22:D29")) -> 0 | E25: =SUMIF(INDIRECT(E$24&"!B22:B29"),$B25,INDIRECT(E$24&"!D22:D29")) -> 0 | F25: =SUMIF(INDIRECT(F$24&"!B22:B29"),$B25,INDIRECT(F$24&"!D22:D29")) -> 0 | G25: =SUMIF(INDIRECT(G$24&"!B22:B29"),$B25,INDIRECT(G$24&"!D22:D29")) -> 0 | H25: =SUMIF(INDIRECT(H$24&"!B22:B29"),$B25,INDIRECT(H$24&"!D22:D29")) -> 0 | I25: =SUMIF(INDIRECT(I$24&"!B22:B29"),$B25,INDIRECT(I$24&"!D22:D29")) -> 0 | J25: =SUMIF(INDIRECT(J$24&"!B22:B29"),$B25,INDIRECT(J$24&"!D22:D29")) -> 325 | ... N25: =SUMIF(INDIRECT(N$24&"!B22:B29"),$B25,INDIRECT(N$24&"!D22:D29")) -> 0
B26: Investment Portfolio | C26: =SUMIF(INDIRECT(C$24&"!B22:B29"),$B26,INDIRECT(C$24&"!D22:D29")) -> 0 | D26: =SUMIF(INDIRECT(D$24&"!B22:B29"),$B26,INDIRECT(D$24&"!D22:D29")) -> 0 | E26: =SUMIF(INDIRECT(E$24&"!B22:B29"),$B26,INDIRECT(E$24&"!D22:D29")) -> 0 | F26: =SUMIF(INDIRECT(F$24&"!B22:B29"),$B26,INDIRECT(F$24&"!D22:D29")) -> 0 | G26: =SUMIF(INDIRECT(G$24&"!B22:B29"),$B26,INDIRECT(G$24&"!D22:D29")) -> 0 | H26: =SUMIF(INDIRECT(H$24&"!B22:B29"),$B26,INDIRECT(H$24&"!D22:D29")) -> 0 | I26: =SUMIF(INDIRECT(I$24&"!B22:B29"),$B26,INDIRECT(I$24&"!D22:D29")) -> 0 | J26: =SUMIF(INDIRECT(J$24&"!B22:B29"),$B26,INDIRECT(J$24&"!D22:D29")) -> 550 | ... N26: =SUMIF(INDIRECT(N$24&"!B22:B29"),$B26,INDIRECT(N$24&"!D22:D29")) -> 0
B27: Vacation Fund | C27: =SUMIF(INDIRECT(C$24&"!B22:B29"),$B27,INDIRECT(C$24&"!D22:D29")) -> 0 | D27: =SUMIF(INDIRECT(D$24&"!B22:B29"),$B27,INDIRECT(D$24&"!D22:D29")) -> 0 | E27: =SUMIF(INDIRECT(E$24&"!B22:B29"),$B27,INDIRECT(E$24&"!D22:D29")) -> 0 | F27: =SUMIF(INDIRECT(F$24&"!B22:B29"),$B27,INDIRECT(F$24&"!D22:D29")) -> 0 | G27: =SUMIF(INDIRECT(G$24&"!B22:B29"),$B27,INDIRECT(G$24&"!D22:D29")) -> 0 | H27: =SUMIF(INDIRECT(H$24&"!B22:B29"),$B27,INDIRECT(H$24&"!D22:D29")) -> 0 | I27: =SUMIF(INDIRECT(I$24&"!B22:B29"),$B27,INDIRECT(I$24&"!D22:D29")) -> 0 | J27: =SUMIF(INDIRECT(J$24&"!B22:B29"),$B27,INDIRECT(J$24&"!D22:D29")) -> 210 | ... N27: =SUMIF(INDIRECT(N$24&"!B22:B29"),$B27,INDIRECT(N$24&"!D22:D29")) -> 0
B28: New Vehicle | C28: =SUMIF(INDIRECT(C$24&"!B22:B29"),$B28,INDIRECT(C$24&"!D22:D29")) -> 0 | D28: =SUMIF(INDIRECT(D$24&"!B22:B29"),$B28,INDIRECT(D$24&"!D22:D29")) -> 0 | E28: =SUMIF(INDIRECT(E$24&"!B22:B29"),$B28,INDIRECT(E$24&"!D22:D29")) -> 0 | F28: =SUMIF(INDIRECT(F$24&"!B22:B29"),$B28,INDIRECT(F$24&"!D22:D29")) -> 0 | G28: =SUMIF(INDIRECT(G$24&"!B22:B29"),$B28,INDIRECT(G$24&"!D22:D29")) -> 0 | H28: =SUMIF(INDIRECT(H$24&"!B22:B29"),$B28,INDIRECT(H$24&"!D22:D29")) -> 0 | I28: =SUMIF(INDIRECT(I$24&"!B22:B29"),$B28,INDIRECT(I$24&"!D22:D29")) -> 0 | J28: =SUMIF(INDIRECT(J$24&"!B22:B29"),$B28,INDIRECT(J$24&"!D22:D29")) -> 550 | ... N28: =SUMIF(INDIRECT(N$24&"!B22:B29"),$B28,INDIRECT(N$24&"!D22:D29")) -> 0
B29: Home Improvement | C29: =SUMIF(INDIRECT(C$24&"!B22:B29"),$B29,INDIRECT(C$24&"!D22:D29")) -> 0 | D29: =SUMIF(INDIRECT(D$24&"!B22:B29"),$B29,INDIRECT(D$24&"!D22:D29")) -> 0 | E29: =SUMIF(INDIRECT(E$24&"!B22:B29"),$B29,INDIRECT(E$24&"!D22:D29")) -> 0 | F29: =SUMIF(INDIRECT(F$24&"!B22:B29"),$B29,INDIRECT(F$24&"!D22:D29")) -> 0 | G29: =SUMIF(INDIRECT(G$24&"!B22:B29"),$B29,INDIRECT(G$24&"!D22:D29")) -> 0 | H29: =SUMIF(INDIRECT(H$24&"!B22:B29"),$B29,INDIRECT(H$24&"!D22:D29")) -> 0 | I29: =SUMIF(INDIRECT(I$24&"!B22:B29"),$B29,INDIRECT(I$24&"!D22:D29")) -> 0 | J29: =SUMIF(INDIRECT(J$24&"!B22:B29"),$B29,INDIRECT(J$24&"!D22:D29")) -> 200 | ... N29: =SUMIF(INDIRECT(N$24&"!B22:B29"),$B29,INDIRECT(N$24&"!D22:D29")) -> 0
C30: =SUMIF(INDIRECT(C$24&"!B22:B29"),$B30,INDIRECT(C$24&"!D22:D29")) -> 0 | D30: =SUMIF(INDIRECT(D$24&"!B22:B29"),$B30,INDIRECT(D$24&"!D22:D29")) -> 0 | E30: =SUMIF(INDIRECT(E$24&"!B22:B29"),$B30,INDIRECT(E$24&"!D22:D29")) -> 0 | F30: =SUMIF(INDIRECT(F$24&"!B22:B29"),$B30,INDIRECT(F$24&"!D22:D29")) -> 0 | G30: =SUMIF(INDIRECT(G$24&"!B22:B29"),$B30,INDIRECT(G$24&"!D22:D29")) -> 0 | H30: =SUMIF(INDIRECT(H$24&"!B22:B29"),$B30,INDIRECT(H$24&"!D22:D29")) -> 0 | I30: =SUMIF(INDIRECT(I$24&"!B22:B29"),$B30,INDIRECT(I$24&"!D22:D29")) -> 0 | J30: =SUMIF(INDIRECT(J$24&"!B22:B29"),$B30,INDIRECT(J$24&"!D22:D29")) -> 0 | ... N30: =SUMIF(INDIRECT(N$24&"!B22:B29"),$B30,INDIRECT(N$24&"!D22:D29")) -> 0
C31: =SUMIF(INDIRECT(C$24&"!B22:B29"),$B31,INDIRECT(C$24&"!D22:D29")) -> 0 | D31: =SUMIF(INDIRECT(D$24&"!B22:B29"),$B31,INDIRECT(D$24&"!D22:D29")) -> 0 | E31: =SUMIF(INDIRECT(E$24&"!B22:B29"),$B31,INDIRECT(E$24&"!D22:D29")) -> 0 | F31: =SUMIF(INDIRECT(F$24&"!B22:B29"),$B31,INDIRECT(F$24&"!D22:D29")) -> 0 | G31: =SUMIF(INDIRECT(G$24&"!B22:B29"),$B31,INDIRECT(G$24&"!D22:D29")) -> 0 | H31: =SUMIF(INDIRECT(H$24&"!B22:B29"),$B31,INDIRECT(H$24&"!D22:D29")) -> 0 | I31: =SUMIF(INDIRECT(I$24&"!B22:B29"),$B31,INDIRECT(I$24&"!D22:D29")) -> 0 | J31: =SUMIF(INDIRECT(J$24&"!B22:B29"),$B31,INDIRECT(J$24&"!D22:D29")) -> 0 | ... N31: =SUMIF(INDIRECT(N$24&"!B22:B29"),$B31,INDIRECT(N$24&"!D22:D29")) -> 0
C32: =SUMIF(INDIRECT(C$24&"!B22:B29"),$B32,INDIRECT(C$24&"!D22:D29")) -> 0 | D32: =SUMIF(INDIRECT(D$24&"!B22:B29"),$B32,INDIRECT(D$24&"!D22:D29")) -> 0 | E32: =SUMIF(INDIRECT(E$24&"!B22:B29"),$B32,INDIRECT(E$24&"!D22:D29")) -> 0 | F32: =SUMIF(INDIRECT(F$24&"!B22:B29"),$B32,INDIRECT(F$24&"!D22:D29")) -> 0 | G32: =SUMIF(INDIRECT(G$24&"!B22:B29"),$B32,INDIRECT(G$24&"!D22:D29")) -> 0 | H32: =SUMIF(INDIRECT(H$24&"!B22:B29"),$B32,INDIRECT(H$24&"!D22:D29")) -> 0 | I32: =SUMIF(INDIRECT(I$24&"!B22:B29"),$B32,INDIRECT(I$24&"!D22:D29")) -> 0 | J32: =SUMIF(INDIRECT(J$24&"!B22:B29"),$B32,INDIRECT(J$24&"!D22:D29")) -> 0 | ... N32: =SUMIF(INDIRECT(N$24&"!B22:B29"),$B32,INDIRECT(N$24&"!D22:D29")) -> 0
B33: Total Savings | C33: =SUM(C25:C32) -> 0 | D33: =SUM(D25:D32) -> 0 | E33: =SUM(E25:E32) -> 0 | F33: =SUM(F25:F32) -> 0 | G33: =SUM(G25:G32) -> 0 | H33: =SUM(H25:H32) -> 0 | I33: =SUM(I25:I32) -> 0 | J33: =SUM(J25:J32) -> 1835 | ... N33: =SUM(N25:N32) -> 0
B35: Bills
B36: Name | C36: JAN | D36: FEB | E36: MAR | F36: APR | G36: MAY | H36: JUN | I36: JUL | J36: AUG | K36: SEP | L36: OCT | M36: NOV | N36: DEC
B37: Electricity | C37: =SUMIF(INDIRECT(C$36&"!F10:F29"),$B37,INDIRECT(C$36&"!H10:H29")) -> 0 | D37: =SUMIF(INDIRECT(D$36&"!F10:F29"),$B37,INDIRECT(D$36&"!H10:H29")) -> 0 | E37: =SUMIF(INDIRECT(E$36&"!F10:F29"),$B37,INDIRECT(E$36&"!H10:H29")) -> 0 | F37: =SUMIF(INDIRECT(F$36&"!F10:F29"),$B37,INDIRECT(F$36&"!H10:H29")) -> 0 | G37: =SUMIF(INDIRECT(G$36&"!F10:F29"),$B37,INDIRECT(G$36&"!H10:H29")) -> 0 | H37: =SUMIF(INDIRECT(H$36&"!F10:F29"),$B37,INDIRECT(H$36&"!H10:H29")) -> 0 | I37: =SUMIF(INDIRECT(I$36&"!F10:F29"),$B37,INDIRECT(I$36&"!H10:H29")) -> 0 | J37: =SUMIF(INDIRECT(J$36&"!F10:F29"),$B37,INDIRECT(J$36&"!H10:H29")) -> 0 | ... N37: =SUMIF(INDIRECT(N$36&"!F10:F29"),$B37,INDIRECT(N$36&"!H10:H29")) -> 0
B38: Water | C38: =SUMIF(INDIRECT(C$36&"!F10:F29"),$B38,INDIRECT(C$36&"!H10:H29")) -> 0 | D38: =SUMIF(INDIRECT(D$36&"!F10:F29"),$B38,INDIRECT(D$36&"!H10:H29")) -> 0 | E38: =SUMIF(INDIRECT(E$36&"!F10:F29"),$B38,INDIRECT(E$36&"!H10:H29")) -> 0 | F38: =SUMIF(INDIRECT(F$36&"!F10:F29"),$B38,INDIRECT(F$36&"!H10:H29")) -> 0 | G38: =SUMIF(INDIRECT(G$36&"!F10:F29"),$B38,INDIRECT(G$36&"!H10:H29")) -> 0 | H38: =SUMIF(INDIRECT(H$36&"!F10:F29"),$B38,INDIRECT(H$36&"!H10:H29")) -> 0 | I38: =SUMIF(INDIRECT(I$36&"!F10:F29"),$B38,INDIRECT(I$36&"!H10:H29")) -> 0 | J38: =SUMIF(INDIRECT(J$36&"!F10:F29"),$B38,INDIRECT(J$36&"!H10:H29")) -> 0 | ... N38: =SUMIF(INDIRECT(N$36&"!F10:F29"),$B38,INDIRECT(N$36&"!H10:H29")) -> 0
B39: Gas | C39: =SUMIF(INDIRECT(C$36&"!F10:F29"),$B39,INDIRECT(C$36&"!H10:H29")) -> 0 | D39: =SUMIF(INDIRECT(D$36&"!F10:F29"),$B39,INDIRECT(D$36&"!H10:H29")) -> 0 | E39: =SUMIF(INDIRECT(E$36&"!F10:F29"),$B39,INDIRECT(E$36&"!H10:H29")) -> 0 | F39: =SUMIF(INDIRECT(F$36&"!F10:F29"),$B39,INDIRECT(F$36&"!H10:H29")) -> 0 | G39: =SUMIF(INDIRECT(G$36&"!F10:F29"),$B39,INDIRECT(G$36&"!H10:H29")) -> 0 | H39: =SUMIF(INDIRECT(H$36&"!F10:F29"),$B39,INDIRECT(H$36&"!H10:H29")) -> 0 | I39: =SUMIF(INDIRECT(I$36&"!F10:F29"),$B39,INDIRECT(I$36&"!H10:H29")) -> 0 | J39: =SUMIF(INDIRECT(J$36&"!F10:F29"),$B39,INDIRECT(J$36&"!H10:H29")) -> 0 | ... N39: =SUMIF(INDIRECT(N$36&"!F10:F29"),$B39,INDIRECT(N$36&"!H10:H29")) -> 0
B40: Internet | C40: =SUMIF(INDIRECT(C$36&"!F10:F29"),$B40,INDIRECT(C$36&"!H10:H29")) -> 0 | D40: =SUMIF(INDIRECT(D$36&"!F10:F29"),$B40,INDIRECT(D$36&"!H10:H29")) -> 0 | E40: =SUMIF(INDIRECT(E$36&"!F10:F29"),$B40,INDIRECT(E$36&"!H10:H29")) -> 0 | F40: =SUMIF(INDIRECT(F$36&"!F10:F29"),$B40,INDIRECT(F$36&"!H10:H29")) -> 0 | G40: =SUMIF(INDIRECT(G$36&"!F10:F29"),$B40,INDIRECT(G$36&"!H10:H29")) -> 0 | H40: =SUMIF(INDIRECT(H$36&"!F10:F29"),$B40,INDIRECT(H$36&"!H10:H29")) -> 0 | I40: =SUMIF(INDIRECT(I$36&"!F10:F29"),$B40,INDIRECT(I$36&"!H10:H29")) -> 0 | J40: =SUMIF(INDIRECT(J$36&"!F10:F29"),$B40,INDIRECT(J$36&"!H10:H29")) -> 0 | ... N40: =SUMIF(INDIRECT(N$36&"!F10:F29"),$B40,INDIRECT(N$36&"!H10:H29")) -> 0
B41: Phone Plan | C41: =SUMIF(INDIRECT(C$36&"!F10:F29"),$B41,INDIRECT(C$36&"!H10:H29")) -> 0 | D41: =SUMIF(INDIRECT(D$36&"!F10:F29"),$B41,INDIRECT(D$36&"!H10:H29")) -> 0 | E41: =SUMIF(INDIRECT(E$36&"!F10:F29"),$B41,INDIRECT(E$36&"!H10:H29")) -> 0 | F41: =SUMIF(INDIRECT(F$36&"!F10:F29"),$B41,INDIRECT(F$36&"!H10:H29")) -> 0 | G41: =SUMIF(INDIRECT(G$36&"!F10:F29"),$B41,INDIRECT(G$36&"!H10:H29")) -> 0 | H41: =SUMIF(INDIRECT(H$36&"!F10:F29"),$B41,INDIRECT(H$36&"!H10:H29")) -> 0 | I41: =SUMIF(INDIRECT(I$36&"!F10:F29"),$B41,INDIRECT(I$36&"!H10:H29")) -> 0 | J41: =SUMIF(INDIRECT(J$36&"!F10:F29"),$B41,INDIRECT(J$36&"!H10:H29")) -> 0 | ... N41: =SUMIF(INDIRECT(N$36&"!F10:F29"),$B41,INDIRECT(N$36&"!H10:H29")) -> 0
B42: Gym Membership | C42: =SUMIF(INDIRECT(C$36&"!F10:F29"),$B42,INDIRECT(C$36&"!H10:H29")) -> 0 | D42: =SUMIF(INDIRECT(D$36&"!F10:F29"),$B42,INDIRECT(D$36&"!H10:H29")) -> 0 | E42: =SUMIF(INDIRECT(E$36&"!F10:F29"),$B42,INDIRECT(E$36&"!H10:H29")) -> 0 | F42: =SUMIF(INDIRECT(F$36&"!F10:F29"),$B42,INDIRECT(F$36&"!H10:H29")) -> 0 | G42: =SUMIF(INDIRECT(G$36&"!F10:F29"),$B42,INDIRECT(G$36&"!H10:H29")) -> 0 | H42: =SUMIF(INDIRECT(H$36&"!F10:F29"),$B42,INDIRECT(H$36&"!H10:H29")) -> 0 | I42: =SUMIF(INDIRECT(I$36&"!F10:F29"),$B42,INDIRECT(I$36&"!H10:H29")) -> 0 | J42: =SUMIF(INDIRECT(J$36&"!F10:F29"),$B42,INDIRECT(J$36&"!H10:H29")) -> 0 | ... N42: =SUMIF(INDIRECT(N$36&"!F10:F29"),$B42,INDIRECT(N$36&"!H10:H29")) -> 0
B43: Car Insurance | C43: =SUMIF(INDIRECT(C$36&"!F10:F29"),$B43,INDIRECT(C$36&"!H10:H29")) -> 0 | D43: =SUMIF(INDIRECT(D$36&"!F10:F29"),$B43,INDIRECT(D$36&"!H10:H29")) -> 0 | E43: =SUMIF(INDIRECT(E$36&"!F10:F29"),$B43,INDIRECT(E$36&"!H10:H29")) -> 0 | F43: =SUMIF(INDIRECT(F$36&"!F10:F29"),$B43,INDIRECT(F$36&"!H10:H29")) -> 0 | G43: =SUMIF(INDIRECT(G$36&"!F10:F29"),$B43,INDIRECT(G$36&"!H10:H29")) -> 0 | H43: =SUMIF(INDIRECT(H$36&"!F10:F29"),$B43,INDIRECT(H$36&"!H10:H29")) -> 0 | I43: =SUMIF(INDIRECT(I$36&"!F10:F29"),$B43,INDIRECT(I$36&"!H10:H29")) -> 0 | J43: =SUMIF(INDIRECT(J$36&"!F10:F29"),$B43,INDIRECT(J$36&"!H10:H29")) -> 0 | ... N43: =SUMIF(INDIRECT(N$36&"!F10:F29"),$B43,INDIRECT(N$36&"!H10:H29")) -> 0
B44: Health Insurance | C44: =SUMIF(INDIRECT(C$36&"!F10:F29"),$B44,INDIRECT(C$36&"!H10:H29")) -> 0 | D44: =SUMIF(INDIRECT(D$36&"!F10:F29"),$B44,INDIRECT(D$36&"!H10:H29")) -> 0 | E44: =SUMIF(INDIRECT(E$36&"!F10:F29"),$B44,INDIRECT(E$36&"!H10:H29")) -> 0 | F44: =SUMIF(INDIRECT(F$36&"!F10:F29"),$B44,INDIRECT(F$36&"!H10:H29")) -> 0 | G44: =SUMIF(INDIRECT(G$36&"!F10:F29"),$B44,INDIRECT(G$36&"!H10:H29")) -> 0 | H44: =SUMIF(INDIRECT(H$36&"!F10:F29"),$B44,INDIRECT(H$36&"!H10:H29")) -> 0 | I44: =SUMIF(INDIRECT(I$36&"!F10:F29"),$B44,INDIRECT(I$36&"!H10:H29")) -> 0 | J44: =SUMIF(INDIRECT(J$36&"!F10:F29"),$B44,INDIRECT(J$36&"!H10:H29")) -> 0 | ... N44: =SUMIF(INDIRECT(N$36&"!F10:F29"),$B44,INDIRECT(N$36&"!H10:H29")) -> 0
...

Sheet Jan
B2: January | F2: Left to Spend | J2: Total Expenses | N2: Remaining Budget
F3: =D18-J3 -> 19000 | J3: =D30+H30+L30+P30 -> 0 | N3: =D18-C30-G30-K30-O30 -> 19000
B5: Income | F5: Balance Overview | J5: Budget (Left) vs Actual (Right) | N5: Spending Overview
B8: Income | F8: Bills | J8: Expenses | N8: Debt
B9: Name | C9: Payday | D9: Amount | F9: Name | G9: Budget | H9: Actual | J9: Name | K9: Budget | L9: Actual | N9: Name | O9: Budget | P9: Actual
B10: =Apr!B10 -> Burs | C10: =Apr!C10 -> 45748 | D10: =Apr!D10 -> 14000 | F10: Electricity | J10: Groceries | N10: Mortgage
B11: =Apr!B11 -> Maaş | C11: =Apr!C11 -> 45769 | D11: =Apr!D11 -> 5000 | F11: Water | J11: Dining Out | N11: Student Loan
F12: Gas | J12: Fuel | N12: Credit Card
F13: Internet | J13: Shopping
F14: Phone Plan | J14: Beauty
F15: Gym Membership | J15: Entertainment
F16: Car Insurance | J16: Travel
F17: Health Insurance | J17: Gifts
B18: Total | D18: =SUM(D10:D17) -> 19000 | J18: Health
J19: Pets
B20: Savings | J20: Custom Expense 1
B21: Name | C21: Budget | D21: Actual | J21: Custom Expense 2
B22: Emergency Fund
B23: Investment Portfolio
B24: Vacation Fund
B25: New Vehicle
B26: Home Improvement
B30: Total | C30: =SUM(C22:C29) -> 0 | D30: =SUM(D22:D29) -> 0 | F30: Total | G30: =SUM(G10:G29) -> 0 | H30: =SUM(H10:H29) -> 0 | J30: Total | K30: =SUM(K10:K29) -> 0 | L30: =SUM(L10:L29) -> 0 | N30: Total | O30: =SUM(O10:O29) -> 0 | P30: =SUM(P10:P29) -> 0

Sheet Feb
B2: February | F2: Left to Spend | J2: Total Expenses | N2: Remaining Budget
F3: =D18-J3 -> 19000 | J3: =D30+H30+L30+P30 -> 0 | N3: =D18-C30-G30-K30-O30 -> 19000
B5: Income | F5: Balance Overview | J5: Budget (Left) vs Actual (Right) | N5: Spending Overview
B8: Income | F8: Bills | J8: Expenses | N8: Debt
B9: Name | C9: Payday | D9: Amount | F9: Name | G9: Budget | H9: Actual | J9: Name | K9: Budget | L9: Actual | N9: Name | O9: Budget | P9: Actual
B10: =Apr!B10 -> Burs | C10: =Apr!C10 -> 45748 | D10: =Apr!D10 -> 14000 | F10: Electricity | J10: Groceries | N10: Mortgage
B11: =Apr!B11 -> Maaş | C11: =Apr!C11 -> 45769 | D11: =Apr!D11 -> 5000 | F11: Water | J11: Dining Out | N11: Student Loan
F12: Gas | J12: Fuel | N12: Credit Card
F13: Internet | J13: Shopping
F14: Phone Plan | J14: Beauty
F15: Gym Membership | J15: Entertainment
F16: Car Insurance | J16: Travel
F17: Health Insurance | J17: Gifts
B18: Total | D18: =SUM(D10:D17) -> 19000 | J18: Health
A19: 30 | J19: Pets
B20: Savings | J20: Custom Expense 1
B21: Name | C21: Budget | D21: Actual | J21: Custom Expense 2
B22: Emergency Fund
B23: Investment Portfolio
B24: Vacation Fund
B25: New Vehicle
B26: Home Improvement
B30: Total | C30: =SUM(C22:C29) -> 0 | D30: =SUM(D22:D29) -> 0 | F30: Total | G30: =SUM(G10:G29) -> 0 | H30: =SUM(H10:H29) -> 0 | J30: Total | K30: =SUM(K10:K29) -> 0 | L30: =SUM(L10:L29) -> 0 | N30: Total | O30: =SUM(O10:O29) -> 0 | P30: =SUM(P10:P29) -> 0

Sheet Mar
B2: March | F2: Left to Spend | J2: Total Expenses | N2: Remaining Budget
F3: =D18-J3 -> -15900 | J3: =D30+H30+L30+P30 -> 34900 | N3: =D18-C30-G30-K30-O30 -> -3500
B5: Income | F5: Balance Overview | J5: Budget (Left) vs Actual (Right) | N5: Spending Overview
B8: Income | F8: Bills | J8: Expenses | N8: Debt
B9: Name | C9: Payday | D9: Amount | F9: Name | G9: Budget | H9: Actual | J9: Name | K9: Budget | L9: Actual | N9: Name | O9: Budget | P9: Actual
B10: =Apr!B10 -> Burs | C10: =Apr!C10 -> 45748 | D10: =Apr!D10 -> 14000 | F10: Electricity | J10: Groceries | N10: Mortgage
B11: =Apr!B11 -> Maaş | C11: =Apr!C11 -> 45769 | D11: =Apr!D11 -> 5000 | F11: Water | J11: Dining Out | N11: Student Loan
F12: Gas | J12: Fuel | N12: Credit Card
F13: Internet | J13: Shopping
F14: Phone Plan | J14: Beauty
F15: Gym Membership | J15: Entertainment
F16: Car Insurance | J16: Travel
F17: Health Insurance | J17: Gifts
B18: Total | D18: =SUM(D10:D17) -> 19000 | J18: Health
J19: Pets
B20: Savings | J20: Custom Expense 1
B21: Name | C21: Budget | D21: Actual | J21: Custom Expense 2
B22: YBL Para fonu | C22: 15000 | D22: 15000
B23: Altın | C23: 7500 | D23: 19900
B30: Total | C30: =SUM(C22:C29) -> 22500 | D30: =SUM(D22:D29) -> 34900 | F30: Total | G30: =SUM(G10:G29) -> 0 | H30: =SUM(H10:H29) -> 0 | J30: Total | K30: =SUM(K10:K29) -> 0 | L30: =SUM(L10:L29) -> 0 | N30: Total | O30: =SUM(O10:O29) -> 0 | P30: =SUM(P10:P29) -> 0

Sheet Apr
B2: April | F2: Left to Spend | J2: Total Expenses | N2: Remaining Budget
F3: =D18-J3 -> 19000 | J3: =D30+H30+L30+P30 -> 0 | N3: =D18-C30-G30-K30-O30 -> 16000
B5: Income | F5: Balance Overview | J5: Budget (Left) vs Actual (Right) | N5: Spending Overview
B8: Income | F8: Bills | J8: Expenses | N8: Debt
B9: Name | C9: Payday | D9: Amount | F9: Name | G9: Budget | H9: Actual | J9: Name | K9: Budget | L9: Actual | N9: Name | O9: Budget | P9: Actual
B10: Burs | C10: =IF(ROW()=9, DATE(2025, 4, 1), DATE(2025, 4, 1)) -> 45748 | D10: 14000 | F10: Electricity | J10: Yiyecek | N10: ahmetcan borç | O10: 3000
B11: Maaş | C11: =IF(ROW()=10, DATE(2025, 4, 1), DATE(2025, 4, 22)) -> 45769 | D11: 5000 | F11: Water | J11: Dining Out
F12: Gas | J12: Fuel
F13: Internet | J13: Shopping
F14: Phone Plan | J14: Beauty
F15: Gym Membership | J15: Entertainment
F16: Car Insurance | J16: Travel
J17: Gifts
B18: Total | D18: =SUM(D10:D17) -> 19000 | J18: Health
J19: Pets
B20: Savings | J20: Custom Expense 1
B21: Name | C21: Budget | D21: Actual | J21: Custom Expense 2
B22: Emergency Fund
B23: Investment Portfolio
B24: Vacation Fund
B25: New Vehicle
B26: Home Improvement
B30: Total | C30: =SUM(C22:C29) -> 0 | D30: =SUM(D22:D29) -> 0 | F30: Total | G30: =SUM(G10:G29) -> 0 | H30: =SUM(H10:H29) -> 0 | J30: Total | K30: =SUM(K10:K29) -> 0 | L30: =SUM(L10:L29) -> 0 | N30: Total | O30: =SUM(O10:O29) -> 3000 | P30: =SUM(P10:P29) -> 0

Sheet May
B2: May | F2: Left to Spend | J2: Total Expenses | N2: Remaining Budget
F3: =D18-J3 -> 19000 | J3: =D30+H30+L30+P30 -> 0 | N3: =D18-C30-G30-K30-O30 -> 19000
B5: Income | F5: Balance Overview | J5: Budget (Left) vs Actual (Right) | N5: Spending Overview
B8: Income | F8: Bills | J8: Expenses | N8: Debt
B9: Name | C9: Payday | D9: Amount | F9: Name | G9: Budget | H9: Actual | J9: Name | K9: Budget | L9: Actual | N9: Name | O9: Budget | P9: Actual
B10: =Apr!B10 -> Burs | C10: =Apr!C10 -> 45748 | D10: =Apr!D10 -> 14000 | F10: Electricity | J10: Groceries | N10: Mortgage
B11: =Apr!B11 -> Maaş | C11: =Apr!C11 -> 45769 | D11: =Apr!D11 -> 5000 | F11: Water | J11: Dining Out | N11: Student Loan
F12: Gas | J12: Fuel | N12: Credit Card
F13: Internet | J13: Shopping
F14: Phone Plan | J14: Beauty
F15: Gym Membership | J15: Entertainment
F16: Car Insurance | J16: Travel
F17: Health Insurance | J17: Gifts
B18: Total | D18: =SUM(D10:D17) -> 19000 | J18: Health
J19: Pets
B20: Savings | J20: Custom Expense 1
B21: Name | C21: Budget | D21: Actual | J21: Custom Expense 2
B22: Emergency Fund
B23: Investment Portfolio
B24: Vacation Fund
B25: New Vehicle
B26: Home Improvement
B30: Total | C30: =SUM(C22:C29) -> 0 | D30: =SUM(D22:D29) -> 0 | F30: Total | G30: =SUM(G10:G29) -> 0 | H30: =SUM(H10:H29) -> 0 | J30: Total | K30: =SUM(K10:K29) -> 0 | L30: =SUM(L10:L29) -> 0 | N30: Total | O30: =SUM(O10:O29) -> 0 | P30: =SUM(P10:P29) -> 0

Sheet Jun
B2: June | F2: Left to Spend | J2: Total Expenses | N2: Remaining Budget
F3: =D18-J3 -> 19000 | J3: =D30+H30+L30+P30 -> 0 | N3: =D18-C30-G30-K30-O30 -> 19000
B5: Income | F5: Balance Overview | J5: Budget (Left) vs Actual (Right) | N5: Spending Overview
B8: Income | F8: Bills | J8: Expenses | N8: Debt
B9: Name | C9: Payday | D9: Amount | F9: Name | G9: Budget | H9: Actual | J9: Name | K9: Budget | L9: Actual | N9: Name | O9: Budget | P9: Actual
B10: =Apr!B10 -> Burs | C10: =Apr!C10 -> 45748 | D10: =Apr!D10 -> 14000 | F10: Electricity | J10: Groceries | N10: Mortgage
B11: =Apr!B11 -> Maaş | C11: =Apr!C11 -> 45769 | D11: =Apr!D11 -> 5000 | F11: Water | J11: Dining Out | N11: Student Loan
F12: Gas | J12: Fuel | N12: Credit Card
F13: Internet | J13: Shopping
F14: Phone Plan | J14: Beauty
F15: Gym Membership | J15: Entertainment
F16: Car Insurance | J16: Travel
F17: Health Insurance | J17: Gifts
B18: Total | D18: =SUM(D10:D17) -> 19000 | J18: Health
J19: Pets
B20: Savings | J20: Custom Expense 1
B21: Name | C21: Budget | D21: Actual | J21: Custom Expense 2
B22: Emergency Fund
B23: Investment Portfolio
B24: Vacation Fund
B25: New Vehicle
B26: Home Improvement
B30: Total | C30: =SUM(C22:C29) -> 0 | D30: =SUM(D22:D29) -> 0 | F30: Total | G30: =SUM(G10:G29) -> 0 | H30: =SUM(H10:H29) -> 0 | J30: Total | K30: =SUM(K10:K29) -> 0 | L30: =SUM(L10:L29) -> 0 | N30: Total | O30: =SUM(O10:O29) -> 0 | P30: =SUM(P10:P29) -> 0

Sheet Jul
B2: July | F2: Left to Spend | J2: Total Expenses | N2: Remaining Budget
F3: =D18-J3 -> 19000 | J3: =D30+H30+L30+P30 -> 0 | N3: =D18-C30-G30-K30-O30 -> 19000
B5: Income | F5: Balance Overview | J5: Budget (Left) vs Actual (Right) | N5: Spending Overview
B8: Income | F8: Bills | J8: Expenses | N8: Debt
B9: Name | C9: Payday | D9: Amount | F9: Name | G9: Budget | H9: Actual | J9: Name | K9: Budget | L9: Actual | N9: Name | O9: Budget | P9: Actual
B10: =Apr!B10 -> Burs | C10: =Apr!C10 -> 45748 | D10: =Apr!D10 -> 14000 | F10: Electricity | J10: Groceries | N10: Mortgage
B11: =Apr!B11 -> Maaş | C11: =Apr!C11 -> 45769 | D11: =Apr!D11 -> 5000 | F11: Water | J11: Dining Out | N11: Student Loan
F12: Gas | J12: Fuel | N12: Credit Card
F13: Internet | J13: Shopping
F14: Phone Plan | J14: Beauty
F15: Gym Membership | J15: Entertainment
F16: Car Insurance | J16: Travel
F17: Health Insurance | J17: Gifts
B18: Total | D18: =SUM(D10:D17) -> 19000 | J18: Health
J19: Pets
B20: Savings | J20: Custom Expense 1
B21: Name | C21: Budget | D21: Actual | J21: Custom Expense 2
B22: Emergency Fund
B23: Investment Portfolio
B24: Vacation Fund
B25: New Vehicle
B26: Home Improvement
B30: Total | C30: =SUM(C22:C29) -> 0 | D30: =SUM(D22:D29) -> 0 | F30: Total | G30: =SUM(G10:G29) -> 0 | H30: =SUM(H10:H29) -> 0 | J30: Total | K30: =SUM(K10:K29) -> 0 | L30: =SUM(L10:L29) -> 0 | N30: Total | O30: =SUM(O10:O29) -> 0 | P30: =SUM(P10:P29) -> 0

Sheet Aug
B2: August | F2: Left to Spend | J2: Total Expenses | N2: Remaining Budget
F3: =D18-J3 -> 15465 | J3: =D30+H30+L30+P30 -> 3535 | N3: =D18-C30-G30-K30-O30 -> 15950
B5: Income | F5: Balance Overview | J5: Budget (Left) vs Actual (Right) | N5: Spending Overview
B8: Income | F8: Bills | J8: Expenses | N8: Debt
B9: Name | C9: Payday | D9: Amount | F9: Name | G9: Budget | H9: Actual | J9: Name | K9: Budget | L9: Actual | N9: Name | O9: Budget | P9: Actual
B10: =Apr!B10 -> Burs | C10: =Apr!C10 -> 45748 | D10: =Apr!D10 -> 14000 | F10: Electricity | J10: Groceries | N10: Mortgage | O10: 900 | P10: 900
B11: =Apr!B11 -> Maaş | C11: =Apr!C11 -> 45769 | D11: =Apr!D11 -> 5000 | F11: Water | J11: Dining Out | N11: Student Loan | O11: 400 | P11: 400
F12: Gas | J12: Fuel | N12: Credit Card | O12: 200 | P12: 400
F13: Internet | J13: Shopping
F14: Phone Plan | J14: Beauty
F15: Gym Membership | J15: Entertainment
F16: Car Insurance | J16: Travel
F17: Health Insurance | J17: Gifts
B18: Total | D18: =SUM(D10:D17) -> 19000 | J18: Health
J19: Pets
B20: Savings | J20: Custom Expense 1
B21: Name | C21: Budget | D21: Actual | J21: Custom Expense 2
B22: Emergency Fund | C22: 300 | D22: 325
B23: Investment Portfolio | C23: 500 | D23: 550
B24: Vacation Fund | C24: 200 | D24: 210
B25: New Vehicle | C25: 400 | D25: 550
B26: Home Improvement | C26: 150 | D26: 200
B30: Total | C30: =SUM(C22:C29) -> 1550 | D30: =SUM(D22:D29) -> 1835 | F30: Total | G30: =SUM(G10:G29) -> 0 | H30: =SUM(H10:H29) -> 0 | J30: Total | K30: =SUM(K10:K29) -> 0 | L30: =SUM(L10:L29) -> 0 | N30: Total | O30: =SUM(O10:O29) -> 1500 | P30: =SUM(P10:P29) -> 1700

Sheet Sep
B2: September | F2: Left to Spend | J2: Total Expenses | N2: Remaining Budget
F3: =D18-J3 -> 19000 | J3: =D30+H30+L30+P30 -> 0 | N3: =D18-C30-G30-K30-O30 -> 19000
B5: Income | F5: Balance Overview | J5: Budget (Left) vs Actual (Right) | N5: Spending Overview
B8: Income | F8: Bills | J8: Expenses | N8: Debt
B9: Name | C9: Payday | D9: Amount | F9: Name | G9: Budget | H9: Actual | J9: Name | K9: Budget | L9: Actual | N9: Name | O9: Budget | P9: Actual
B10: =Apr!B10 -> Burs | C10: =Apr!C10 -> 45748 | D10: =Apr!D10 -> 14000 | F10: Electricity | J10: Groceries | N10: Mortgage
B11: =Apr!B11 -> Maaş | C11: =Apr!C11 -> 45769 | D11: =Apr!D11 -> 5000 | F11: Water | J11: Dining Out | N11: Student Loan
F12: Gas | J12: Fuel | N12: Credit Card
F13: Internet | J13: Shopping
F14: Phone Plan | J14: Beauty
F15: Gym Membership | J15: Entertainment
F16: Car Insurance | J16: Travel
F17: Health Insurance | J17: Gifts
B18: Total | D18: =SUM(D10:D17) -> 19000 | J18: Health
J19: Pets
B20: Savings | J20: Custom Expense 1
B21: Name | C21: Budget | D21: Actual | J21: Custom Expense 2
B22: Emergency Fund
B23: Investment Portfolio
B24: Vacation Fund
B25: New Vehicle
B26: Home Improvement
B30: Total | C30: =SUM(C22:C29) -> 0 | D30: =SUM(D22:D29) -> 0 | F30: Total | G30: =SUM(G10:G29) -> 0 | H30: =SUM(H10:H29) -> 0 | J30: Total | K30: =SUM(K10:K29) -> 0 | L30: =SUM(L10:L29) -> 0 | N30: Total | O30: =SUM(O10:O29) -> 0 | P30: =SUM(P10:P29) -> 0

Sheet Oct
B2: October | F2: Left to Spend | J2: Total Expenses | N2: Remaining Budget
F3: =D18-J3 -> 19000 | J3: =D30+H30+L30+P30 -> 0 | N3: =D18-C30-G30-K30-O30 -> 19000
B5: Income | F5: Balance Overview | J5: Budget (Left) vs Actual (Right) | N5: Spending Overview
B8: Income | F8: Bills | J8: Expenses | N8: Debt
B9: Name | C9: Payday | D9: Amount | F9: Name | G9: Budget | H9: Actual | J9: Name | K9: Budget | L9: Actual | N9: Name | O9: Budget | P9: Actual
B10: =Apr!B10 -> Burs | C10: =Apr!C10 -> 45748 | D10: =Apr!D10 -> 14000 | F10: Electricity | J10: Groceries | N10: Mortgage
B11: =Apr!B11 -> Maaş | C11: =Apr!C11 -> 45769 | D11: =Apr!D11 -> 5000 | F11: Water | J11: Dining Out | N11: Student Loan
F12: Gas | J12: Fuel | N12: Credit Card
F13: Internet | J13: Shopping
F14: Phone Plan | J14: Beauty
F15: Gym Membership | J15: Entertainment
F16: Car Insurance | J16: Travel
F17: Health Insurance | J17: Gifts
B18: Total | D18: =SUM(D10:D17) -> 19000 | J18: Health
J19: Pets
B20: Savings | J20: Custom Expense 1
B21: Name | C21: Budget | D21: Actual | J21: Custom Expense 2
B22: Emergency Fund
B23: Investment Portfolio
B24: Vacation Fund
B25: New Vehicle
B26: Home Improvement
B30: Total | C30: =SUM(C22:C29) -> 0 | D30: =SUM(D22:D29) -> 0 | F30: Total | G30: =SUM(G10:G29) -> 0 | H30: =SUM(H10:H29) -> 0 | J30: Total | K30: =SUM(K10:K29) -> 0 | L30: =SUM(L10:L29) -> 0 | N30: Total | O30: =SUM(O10:O29) -> 0 | P30: =SUM(P10:P29) -> 0

Sheet Nov
B2: November | F2: Left to Spend | J2: Total Expenses | N2: Remaining Budget
F3: =D18-J3 -> 19000 | J3: =D30+H30+L30+P30 -> 0 | N3: =D18-C30-G30-K30-O30 -> 19000
B5: Income | F5: Balance Overview | J5: Budget (Left) vs Actual (Right) | N5: Spending Overview
B8: Income | F8: Bills | J8: Expenses | N8: Debt
B9: Name | C9: Payday | D9: Amount | F9: Name | G9: Budget | H9: Actual | J9: Name | K9: Budget | L9: Actual | N9: Name | O9: Budget | P9: Actual
B10: =Apr!B10 -> Burs | C10: =Apr!C10 -> 45748 | D10: =Apr!D10 -> 14000 | F10: Electricity | J10: Groceries | N10: Mortgage
B11: =Apr!B11 -> Maaş | C11: =Apr!C11 -> 45769 | D11: =Apr!D11 -> 5000 | F11: Water | J11: Dining Out | N11: Student Loan
F12: Gas | J12: Fuel | N12: Credit Card
F13: Internet | J13: Shopping
F14: Phone Plan | J14: Beauty
F15: Gym Membership | J15: Entertainment
F16: Car Insurance | J16: Travel
F17: Health Insurance | J17: Gifts
B18: Total | D18: =SUM(D10:D17) -> 19000 | J18: Health
J19: Pets
B20: Savings | J20: Custom Expense 1
B21: Name | C21: Budget | D21: Actual | J21: Custom Expense 2
B22: Emergency Fund
B23: Investment Portfolio
B24: Vacation Fund
B25: New Vehicle
B26: Home Improvement
B30: Total | C30: =SUM(C22:C29) -> 0 | D30: =SUM(D22:D29) -> 0 | F30: Total | G30: =SUM(G10:G29) -> 0 | H30: =SUM(H10:H29) -> 0 | J30: Total | K30: =SUM(K10:K29) -> 0 | L30: =SUM(L10:L29) -> 0 | N30: Total | O30: =SUM(O10:O29) -> 0 | P30: =SUM(P10:P29) -> 0

Sheet Dec
B2: December | F2: Left to Spend | J2: Total Expenses | N2: Remaining Budget
F3: =D18-J3 -> 19000 | J3: =D30+H30+L30+P30 -> 0 | N3: =D18-C30-G30-K30-O30 -> 19000
B5: Income | F5: Balance Overview | J5: Budget (Left) vs Actual (Right) | N5: Spending Overview
B8: Income | F8: Bills | J8: Expenses | N8: Debt
B9: Name | C9: Payday | D9: Amount | F9: Name | G9: Budget | H9: Actual | J9: Name | K9: Budget | L9: Actual | N9: Name | O9: Budget | P9: Actual
B10: =Apr!B10 -> Burs | C10: =Apr!C10 -> 45748 | D10: =Apr!D10 -> 14000 | F10: Electricity | J10: Groceries | N10: Mortgage
B11: =Apr!B11 -> Maaş | C11: =Apr!C11 -> 45769 | D11: =Apr!D11 -> 5000 | F11: Water | J11: Dining Out | N11: Student Loan
F12: Gas | J12: Fuel | N12: Credit Card
F13: Internet | J13: Shopping
F14: Phone Plan | J14: Beauty
F15: Gym Membership | J15: Entertainment
F16: Car Insurance | J16: Travel
F17: Health Insurance | J17: Gifts
B18: Total | D18: =SUM(D10:D17) -> 19000 | J18: Health
J19: Pets
B20: Savings | J20: Custom Expense 1
B21: Name | C21: Budget | D21: Actual | J21: Custom Expense 2
B22: Emergency Fund
B23: Investment Portfolio
B24: Vacation Fund
B25: New Vehicle
B26: Home Improvement
B30: Total | C30: =SUM(C22:C29) -> 0 | D30: =SUM(D22:D29) -> 0 | F30: Total | G30: =SUM(G10:G29) -> 0 | H30: =SUM(H10:H29) -> 0 | J30: Total | K30: =SUM(K10:K29) -> 0 | L30: =SUM(L10:L29) -> 0 | N30: Total | O30: =SUM(O10:O29) -> 0 | P30: =SUM(P10:P29) -> 0

Sheet Chart Data for Each Month
B2: Budget (Left) vs Actual (Right) Jan | F2: Budget (Left) vs Actual (Right) Feb | J2: Budget (Left) vs Actual (Right) Mar | N2: Budget (Left) vs Actual (Right) Apr | R2: Budget (Left) vs Actual (Right) May | V2: Budget (Left) vs Actual (Right) Jun
B3: Name | C3: Budget | D3: Actual | F3: Name | G3: Budget | H3: Actual | J3: Name | K3: Budget | L3: Actual | N3: Name | O3: Budget | P3: Actual | R3: Name | S3: Budget | T3: Actual | V3: Name | W3: Budget | X3: Actual
B4: Savings | C4: =Jan!C30 -> 0 | D4: =Jan!D30 -> 0 | F4: Savings | G4: =Feb!C30 -> 0 | H4: =Feb!D30 -> 0 | J4: Savings | K4: =Mar!C30 -> 22500 | L4: =Mar!D30 -> 34900 | N4: Savings | O4: =Apr!$C30 -> 0 | P4: =Apr!$D30 -> 0 | R4: Savings | S4: =May!$C30 -> 0 | T4: =May!$D30 -> 0 | V4: Savings | W4: =Jun!$C30 -> 0 | X4: =Jun!$D30 -> 0
B5: Bills | C5: =Jan!G30 -> 0 | D5: =Jan!H30 -> 0 | F5: Bills | G5: =Feb!G30 -> 0 | H5: =Feb!H30 -> 0 | J5: Bills | K5: =Mar!G30 -> 0 | L5: =Mar!H30 -> 0 | N5: Bills | O5: =Apr!$G30 -> 0 | P5: =Apr!$H30 -> 0 | R5: Bills | S5: =May!$G30 -> 0 | T5: =May!$H30 -> 0 | V5: Bills | W5: =Jun!$G30 -> 0 | X5: =Jun!$H30 -> 0
B6: Expenses | C6: =Jan!K30 -> 0 | D6: =Jan!L30 -> 0 | F6: Expenses | G6: =Feb!K30 -> 0 | H6: =Feb!L30 -> 0 | J6: Expenses | K6: =Mar!K30 -> 0 | L6: =Mar!L30 -> 0 | N6: Expenses | O6: =Apr!$K30 -> 0 | P6: =Apr!$L30 -> 0 | R6: Expenses | S6: =May!$K30 -> 0 | T6: =May!$L30 -> 0 | V6: Expenses | W6: =Jun!$K30 -> 0 | X6: =Jun!$L30 -> 0
B7: Debt | C7: =Jan!O30 -> 0 | D7: =Jan!P30 -> 0 | F7: Debt | G7: =Feb!O30 -> 0 | H7: =Feb!P30 -> 0 | J7: Debt | K7: =Mar!O30 -> 0 | L7: =Mar!P30 -> 0 | N7: Debt | O7: =Apr!$O30 -> 3000 | P7: =Apr!$P30 -> 0 | R7: Debt | S7: =May!$O30 -> 0 | T7: =May!$P30 -> 0 | V7: Debt | W7: =Jun!$O30 -> 0 | X7: =Jun!$P30 -> 0
B8: Spending Overview Jan | F8: Spending Overview Feb | J8: Spending Overview Mar | N8: Spending Overview Apr | R8: Spending Overview May | V8: Spending Overview Jun
B9: Name | C9: Amount | F9: Name | G9: Amount | J9: Name | K9: Amount | N9: Name | O9: Amount | R9: Name | S9: Amount | V9: Name | W9: Amount
B10: Savings | C10: =Jan!D30 -> 0 | F10: Savings | G10: =Feb!D30 -> 0 | J10: Savings | K10: =Mar!D30 -> 34900 | N10: Savings | O10: =Apr!D30 -> 0 | R10: Savings | S10: =May!$D30 -> 0 | V10: Savings | W10: =Jun!$D30 -> 0
B11: Bills | C11: =Jan!H30 -> 0 | F11: Bills | G11: =Feb!H30 -> 0 | J11: Bills | K11: =Mar!H30 -> 0 | N11: Bills | O11: =Apr!H30 -> 0 | R11: Bills | S11: =May!$H30 -> 0 | V11: Bills | W11: =Jun!$H30 -> 0
B12: Expenses | C12: =Jan!L30 -> 0 | F12: Expenses | G12: =Feb!L30 -> 0 | J12: Expenses | K12: =Mar!L30 -> 0 | N12: Expenses | O12: =Apr!L30 -> 0 | R12: Expenses | S12: =May!$L30 -> 0 | V12: Expenses | W12: =Jun!$L30 -> 0
B13: Debt | C13: =Jan!P30 -> 0 | F13: Debt | G13: =Feb!P30 -> 0 | J13: Debt | K13: =Mar!P30 -> 0 | N13: Debt | O13: =Apr!P30 -> 0 | R13: Debt | S13: =May!$P30 -> 0 | V13: Debt | W13: =Jun!$P30 -> 0
B15: Budget (Left) vs Actual (Right) Jul | F15: Budget (Left) vs Actual (Right) Aug | J15: Budget (Left) vs Actual (Right) Sep | N15: Budget (Left) vs Actual (Right) Oct | R15: Budget (Left) vs Actual (Right) Nov | V15: Budget (Left) vs Actual (Right) Dec
B16: Name | C16: Budget | D16: Actual | F16: Name | G16: Budget | H16: Actual | J16: Name | K16: Budget | L16: Actual | N16: Name | O16: Budget | P16: Actual | R16: Name | S16: Budget | T16: Actual | V16: Name | W16: Budget | X16: Actual
B17: Savings | C17: =Jul!$C30 -> 0 | D17: =Jul!$D30 -> 0 | F17: Savings | G17: =Aug!$C30 -> 1550 | H17: =Aug!$D30 -> 1835 | J17: Savings | K17: =Sep!$C30 -> 0 | L17: =Sep!$D30 -> 0 | N17: Savings | O17: =Oct!$C30 -> 0 | P17: =Oct!$D30 -> 0 | R17: Savings | S17: =Nov!$C30 -> 0 | T17: =Nov!$D30 -> 0 | V17: Savings | W17: =Dec!$C30 -> 0 | X17: =Dec!$D30 -> 0
B18: Bills | C18: =Jul!$G30 -> 0 | D18: =Jul!$H30 -> 0 | F18: Bills | G18: =Aug!$G30 -> 0 | H18: =Aug!$H30 -> 0 | J18: Bills | K18: =Sep!$G30 -> 0 | L18: =Sep!$H30 -> 0 | N18: Bills | O18: =Oct!$G30 -> 0 | P18: =Oct!$H30 -> 0 | R18: Bills | S18: =Nov!$G30 -> 0 | T18: =Nov!$H30 -> 0 | V18: Bills | W18: =Dec!$G30 -> 0 | X18: =Dec!$H30 -> 0
B19: Expenses | C19: =Jul!$K30 -> 0 | D19: =Jul!$L30 -> 0 | F19: Expenses | G19: =Aug!$K30 -> 0 | H19: =Aug!$L30 -> 0 | J19: Expenses | K19: =Sep!$K30 -> 0 | L19: =Sep!$L30 -> 0 | N19: Expenses | O19: =Oct!$K30 -> 0 | P19: =Oct!$L30 -> 0 | R19: Expenses | S19: =Nov!$K30 -> 0 | T19: =Nov!$L30 -> 0 | V19: Expenses | W19: =Dec!$K30 -> 0 | X19: =Dec!$L30 -> 0
B20: Debt | C20: =Jul!$O30 -> 0 | D20: =Jul!$P30 -> 0 | F20: Debt | G20: =Aug!$O30 -> 1500 | H20: =Aug!$P30 -> 1700 | J20: Debt | K20: =Sep!$O30 -> 0 | L20: =Sep!$P30 -> 0 | N20: Debt | O20: =Oct!$O30 -> 0 | P20: =Oct!$P30 -> 0 | R20: Debt | S20: =Nov!$O30 -> 0 | T20: =Nov!$P30 -> 0 | V20: Debt | W20: =Dec!$O30 -> 0 | X20: =Dec!$P30 -> 0
B21: Spending Overview Jul | F21: Spending Overview Aug | J21: Spending Overview Sep | N21: Spending Overview Oct | R21: Spending Overview Nov | V21: Spending Overview Dec
B22: Name | C22: Amount | F22: Name | G22: Amount | J22: Name | K22: Amount | N22: Name | O22: Amount | R22: Name | S22: Amount | V22: Name | W22: Amount
B23: Savings | C23: =Jul!$D30 -> 0 | F23: Savings | G23: =Aug!$D30 -> 1835 | J23: Savings | K23: =Sep!$D30 -> 0 | N23: Savings | O23: =Oct!$D30 -> 0 | R23: Savings | S23: =Nov!$D30 -> 0 | V23: Savings | W23: =Dec!$D30 -> 0
B24: Bills | C24: =Jul!$H30 -> 0 | F24: Bills | G24: =Aug!$H30 -> 0 | J24: Bills | K24: =Sep!$H30 -> 0 | N24: Bills | O24: =Oct!$H30 -> 0 | R24: Bills | S24: =Nov!$H30 -> 0 | V24: Bills | W24: =Dec!$H30 -> 0
B25: Expenses | C25: =Jul!$L30 -> 0 | F25: Expenses | G25: =Aug!$L30 -> 0 | J25: Expenses | K25: =Sep!$L30 -> 0 | N25: Expenses | O25: =Oct!$L30 -> 0 | R25: Expenses | S25: =Nov!$L30 -> 0 | V25: Expenses | W25: =Dec!$L30 -> 0
B26: Debt | C26: =Jul!$P30 -> 0 | F26: Debt | G26: =Aug!$P30 -> 1700 | J26: Debt | K26: =Sep!$P30 -> 0 | N26: Debt | O26: =Oct!$P30 -> 0 | R26: Debt | S26: =Nov!$P30 -> 0 | V26: Debt | W26: =Dec!$P30 -> 0
